[2021-05-11 16:09:30,825] {taskinstance.py:877} INFO - Dependencies all met for <TaskInstance: etl.loading_data_to_s3 2021-05-11T19:09:18.754956+00:00 [queued]>
[2021-05-11 16:09:30,832] {taskinstance.py:877} INFO - Dependencies all met for <TaskInstance: etl.loading_data_to_s3 2021-05-11T19:09:18.754956+00:00 [queued]>
[2021-05-11 16:09:30,832] {taskinstance.py:1068} INFO - 
--------------------------------------------------------------------------------
[2021-05-11 16:09:30,832] {taskinstance.py:1069} INFO - Starting attempt 1 of 1
[2021-05-11 16:09:30,832] {taskinstance.py:1070} INFO - 
--------------------------------------------------------------------------------
[2021-05-11 16:09:30,838] {taskinstance.py:1089} INFO - Executing <Task(BashOperator): loading_data_to_s3> on 2021-05-11T19:09:18.754956+00:00
[2021-05-11 16:09:30,840] {standard_task_runner.py:52} INFO - Started process 98603 to run task
[2021-05-11 16:09:30,847] {standard_task_runner.py:76} INFO - Running: ['airflow', 'tasks', 'run', 'etl', 'loading_data_to_s3', '2021-05-11T19:09:18.754956+00:00', '--job-id', '59', '--pool', 'default_pool', '--raw', '--subdir', 'DAGS_FOLDER/etl.py', '--cfg-path', '/var/folders/_f/vg3x3jmj23bcz6s88l7v6fb40000gn/T/tmp8pa5eixf', '--error-file', '/var/folders/_f/vg3x3jmj23bcz6s88l7v6fb40000gn/T/tmp47ul6dap']
[2021-05-11 16:09:30,848] {standard_task_runner.py:77} INFO - Job 59: Subtask loading_data_to_s3
[2021-05-11 16:09:30,878] {logging_mixin.py:104} INFO - Running <TaskInstance: etl.loading_data_to_s3 2021-05-11T19:09:18.754956+00:00 [running]> on host 27.2.168.192.in-addr.arpa
[2021-05-11 16:09:30,901] {taskinstance.py:1283} INFO - Exporting the following env vars:
AIRFLOW_CTX_DAG_OWNER=airflow
AIRFLOW_CTX_DAG_ID=etl
AIRFLOW_CTX_TASK_ID=loading_data_to_s3
AIRFLOW_CTX_EXECUTION_DATE=2021-05-11T19:09:18.754956+00:00
AIRFLOW_CTX_DAG_RUN_ID=manual__2021-05-11T19:09:18.754956+00:00
[2021-05-11 16:09:30,902] {bash.py:135} INFO - Tmp dir root location: 
 /var/folders/_f/vg3x3jmj23bcz6s88l7v6fb40000gn/T
[2021-05-11 16:09:30,903] {bash.py:158} INFO - Running command: cat ./loading_data_to_s3.py
[2021-05-11 16:09:30,909] {bash.py:169} INFO - Output:
[2021-05-11 16:09:30,913] {bash.py:173} INFO - cat: ./loading_data_to_s3.py: No such file or directory
[2021-05-11 16:09:30,913] {bash.py:177} INFO - Command exited with return code 1
[2021-05-11 16:09:30,919] {taskinstance.py:1482} ERROR - Task failed with exception
Traceback (most recent call last):
  File "/Library/Frameworks/Python.framework/Versions/3.7/lib/python3.7/site-packages/airflow/models/taskinstance.py", line 1138, in _run_raw_task
    self._prepare_and_execute_task_with_callbacks(context, task)
  File "/Library/Frameworks/Python.framework/Versions/3.7/lib/python3.7/site-packages/airflow/models/taskinstance.py", line 1311, in _prepare_and_execute_task_with_callbacks
    result = self._execute_task(context, task_copy)
  File "/Library/Frameworks/Python.framework/Versions/3.7/lib/python3.7/site-packages/airflow/models/taskinstance.py", line 1341, in _execute_task
    result = task_copy.execute(context=context)
  File "/Library/Frameworks/Python.framework/Versions/3.7/lib/python3.7/site-packages/airflow/operators/bash.py", line 180, in execute
    raise AirflowException('Bash command failed. The command returned a non-zero exit code.')
airflow.exceptions.AirflowException: Bash command failed. The command returned a non-zero exit code.
[2021-05-11 16:09:30,923] {taskinstance.py:1532} INFO - Marking task as FAILED. dag_id=etl, task_id=loading_data_to_s3, execution_date=20210511T190918, start_date=20210511T190930, end_date=20210511T190930
[2021-05-11 16:09:30,942] {local_task_job.py:146} INFO - Task exited with return code 1
