[2021-05-11 15:54:54,333] {taskinstance.py:877} INFO - Dependencies all met for <TaskInstance: etl.create_main_table 2021-05-11T18:54:52.177773+00:00 [queued]>
[2021-05-11 15:54:54,339] {taskinstance.py:877} INFO - Dependencies all met for <TaskInstance: etl.create_main_table 2021-05-11T18:54:52.177773+00:00 [queued]>
[2021-05-11 15:54:54,339] {taskinstance.py:1068} INFO - 
--------------------------------------------------------------------------------
[2021-05-11 15:54:54,339] {taskinstance.py:1069} INFO - Starting attempt 1 of 1
[2021-05-11 15:54:54,339] {taskinstance.py:1070} INFO - 
--------------------------------------------------------------------------------
[2021-05-11 15:54:54,345] {taskinstance.py:1089} INFO - Executing <Task(ExecuteQueryOperator): create_main_table> on 2021-05-11T18:54:52.177773+00:00
[2021-05-11 15:54:54,347] {standard_task_runner.py:52} INFO - Started process 98322 to run task
[2021-05-11 15:54:54,353] {standard_task_runner.py:76} INFO - Running: ['airflow', 'tasks', 'run', 'etl', 'create_main_table', '2021-05-11T18:54:52.177773+00:00', '--job-id', '41', '--pool', 'default_pool', '--raw', '--subdir', 'DAGS_FOLDER/etl.py', '--cfg-path', '/var/folders/_f/vg3x3jmj23bcz6s88l7v6fb40000gn/T/tmpx_kzj0kx', '--error-file', '/var/folders/_f/vg3x3jmj23bcz6s88l7v6fb40000gn/T/tmpkgss2k1d']
[2021-05-11 15:54:54,355] {standard_task_runner.py:77} INFO - Job 41: Subtask create_main_table
[2021-05-11 15:54:54,386] {logging_mixin.py:104} INFO - Running <TaskInstance: etl.create_main_table 2021-05-11T18:54:52.177773+00:00 [running]> on host 27.2.168.192.in-addr.arpa
[2021-05-11 15:54:54,408] {taskinstance.py:1283} INFO - Exporting the following env vars:
AIRFLOW_CTX_DAG_OWNER=udacity
AIRFLOW_CTX_DAG_ID=etl
AIRFLOW_CTX_TASK_ID=create_main_table
AIRFLOW_CTX_EXECUTION_DATE=2021-05-11T18:54:52.177773+00:00
AIRFLOW_CTX_DAG_RUN_ID=manual__2021-05-11T18:54:52.177773+00:00
[2021-05-11 15:54:54,409] {execute_query.py:21} INFO - Executing query
[2021-05-11 15:54:54,412] {base.py:78} INFO - Using connection to: id: redshift. Host: redshift-cluster-1.caua6g9a7jto.us-east-1.redshift.amazonaws.com, Port: 5439, Schema: dev, Login: awsuser, Password: XXXXXXXX, extra: None
[2021-05-11 15:54:55,580] {dbapi.py:180} INFO - Running statement: 
    CREATE TABLE IF NOT EXISTS forex.binary_options_historical_quotes (
        quote_sk BIGINT IDENTITY (0, 1),
        date_seconds TIMESTAMP,
        active_id INT,
        value NUMERIC (1, 6),
        PRIMARY KEY (quote_sk)
    );
, parameters: None
[2021-05-11 15:54:55,892] {taskinstance.py:1482} ERROR - Task failed with exception
Traceback (most recent call last):
  File "/Library/Frameworks/Python.framework/Versions/3.7/lib/python3.7/site-packages/airflow/models/taskinstance.py", line 1138, in _run_raw_task
    self._prepare_and_execute_task_with_callbacks(context, task)
  File "/Library/Frameworks/Python.framework/Versions/3.7/lib/python3.7/site-packages/airflow/models/taskinstance.py", line 1311, in _prepare_and_execute_task_with_callbacks
    result = self._execute_task(context, task_copy)
  File "/Library/Frameworks/Python.framework/Versions/3.7/lib/python3.7/site-packages/airflow/models/taskinstance.py", line 1341, in _execute_task
    result = task_copy.execute(context=context)
  File "/Users/raphaelcarvalho/Documents/forex/plugins/execute_query.py", line 22, in execute
    redshift.run(self.query)
  File "/Library/Frameworks/Python.framework/Versions/3.7/lib/python3.7/site-packages/airflow/hooks/dbapi.py", line 184, in run
    cur.execute(sql_statement)
psycopg2.DataError: NUMERIC scale 6 must be between 0 and 1

[2021-05-11 15:54:55,899] {taskinstance.py:1532} INFO - Marking task as FAILED. dag_id=etl, task_id=create_main_table, execution_date=20210511T185452, start_date=20210511T185454, end_date=20210511T185455
[2021-05-11 15:54:55,943] {local_task_job.py:146} INFO - Task exited with return code 1
