[2021-05-11 16:01:40,490] {taskinstance.py:877} INFO - Dependencies all met for <TaskInstance: etl.loading_data_to_s3 2021-05-11T19:01:29.771736+00:00 [queued]>
[2021-05-11 16:01:40,495] {taskinstance.py:877} INFO - Dependencies all met for <TaskInstance: etl.loading_data_to_s3 2021-05-11T19:01:29.771736+00:00 [queued]>
[2021-05-11 16:01:40,495] {taskinstance.py:1068} INFO - 
--------------------------------------------------------------------------------
[2021-05-11 16:01:40,495] {taskinstance.py:1069} INFO - Starting attempt 1 of 1
[2021-05-11 16:01:40,495] {taskinstance.py:1070} INFO - 
--------------------------------------------------------------------------------
[2021-05-11 16:01:40,500] {taskinstance.py:1089} INFO - Executing <Task(BashOperator): loading_data_to_s3> on 2021-05-11T19:01:29.771736+00:00
[2021-05-11 16:01:40,503] {standard_task_runner.py:52} INFO - Started process 98439 to run task
[2021-05-11 16:01:40,510] {standard_task_runner.py:76} INFO - Running: ['airflow', 'tasks', 'run', 'etl', 'loading_data_to_s3', '2021-05-11T19:01:29.771736+00:00', '--job-id', '47', '--pool', 'default_pool', '--raw', '--subdir', 'DAGS_FOLDER/etl.py', '--cfg-path', '/var/folders/_f/vg3x3jmj23bcz6s88l7v6fb40000gn/T/tmpzpepj1_o', '--error-file', '/var/folders/_f/vg3x3jmj23bcz6s88l7v6fb40000gn/T/tmp7sjlx8j4']
[2021-05-11 16:01:40,512] {standard_task_runner.py:77} INFO - Job 47: Subtask loading_data_to_s3
[2021-05-11 16:01:40,544] {logging_mixin.py:104} INFO - Running <TaskInstance: etl.loading_data_to_s3 2021-05-11T19:01:29.771736+00:00 [running]> on host 27.2.168.192.in-addr.arpa
[2021-05-11 16:01:40,569] {taskinstance.py:1283} INFO - Exporting the following env vars:
AIRFLOW_CTX_DAG_OWNER=airflow
AIRFLOW_CTX_DAG_ID=etl
AIRFLOW_CTX_TASK_ID=loading_data_to_s3
AIRFLOW_CTX_EXECUTION_DATE=2021-05-11T19:01:29.771736+00:00
AIRFLOW_CTX_DAG_RUN_ID=manual__2021-05-11T19:01:29.771736+00:00
[2021-05-11 16:01:40,569] {bash.py:135} INFO - Tmp dir root location: 
 /var/folders/_f/vg3x3jmj23bcz6s88l7v6fb40000gn/T
[2021-05-11 16:01:40,570] {bash.py:158} INFO - Running command: python3 /forex/loading_data_to_s3.py
[2021-05-11 16:01:40,577] {bash.py:169} INFO - Output:
[2021-05-11 16:01:40,614] {bash.py:173} INFO - /Library/Frameworks/Python.framework/Versions/3.7/Resources/Python.app/Contents/MacOS/Python: can't open file '/forex/loading_data_to_s3.py': [Errno 2] No such file or directory
[2021-05-11 16:01:40,617] {bash.py:177} INFO - Command exited with return code 2
[2021-05-11 16:01:40,623] {taskinstance.py:1482} ERROR - Task failed with exception
Traceback (most recent call last):
  File "/Library/Frameworks/Python.framework/Versions/3.7/lib/python3.7/site-packages/airflow/models/taskinstance.py", line 1138, in _run_raw_task
    self._prepare_and_execute_task_with_callbacks(context, task)
  File "/Library/Frameworks/Python.framework/Versions/3.7/lib/python3.7/site-packages/airflow/models/taskinstance.py", line 1311, in _prepare_and_execute_task_with_callbacks
    result = self._execute_task(context, task_copy)
  File "/Library/Frameworks/Python.framework/Versions/3.7/lib/python3.7/site-packages/airflow/models/taskinstance.py", line 1341, in _execute_task
    result = task_copy.execute(context=context)
  File "/Library/Frameworks/Python.framework/Versions/3.7/lib/python3.7/site-packages/airflow/operators/bash.py", line 180, in execute
    raise AirflowException('Bash command failed. The command returned a non-zero exit code.')
airflow.exceptions.AirflowException: Bash command failed. The command returned a non-zero exit code.
[2021-05-11 16:01:40,626] {taskinstance.py:1532} INFO - Marking task as FAILED. dag_id=etl, task_id=loading_data_to_s3, execution_date=20210511T190129, start_date=20210511T190140, end_date=20210511T190140
[2021-05-11 16:01:40,650] {local_task_job.py:146} INFO - Task exited with return code 1
